[2021-12-09 19:00:57,308] {taskinstance.py:1035} INFO - Dependencies all met for <TaskInstance: brent_pricing_dag.Create_dummy_variables manual__2021-12-09T23:54:02.861896+00:00 [queued]>
[2021-12-09 19:00:57,314] {taskinstance.py:1035} INFO - Dependencies all met for <TaskInstance: brent_pricing_dag.Create_dummy_variables manual__2021-12-09T23:54:02.861896+00:00 [queued]>
[2021-12-09 19:00:57,314] {taskinstance.py:1241} INFO - 
--------------------------------------------------------------------------------
[2021-12-09 19:00:57,314] {taskinstance.py:1242} INFO - Starting attempt 1 of 1
[2021-12-09 19:00:57,314] {taskinstance.py:1243} INFO - 
--------------------------------------------------------------------------------
[2021-12-09 19:00:57,323] {taskinstance.py:1262} INFO - Executing <Task(PythonOperator): Create_dummy_variables> on 2021-12-09 23:54:02.861896+00:00
[2021-12-09 19:00:57,325] {standard_task_runner.py:52} INFO - Started process 33879 to run task
[2021-12-09 19:00:57,331] {standard_task_runner.py:76} INFO - Running: ['airflow', 'tasks', 'run', 'brent_pricing_dag', 'Create_dummy_variables', 'manual__2021-12-09T23:54:02.861896+00:00', '--job-id', '77', '--raw', '--subdir', 'DAGS_FOLDER/dag_brent_pricing.py', '--cfg-path', '/var/folders/b3/j_ybgjv53p33dy62wlktdr4m0000gp/T/tmpv0t70377', '--error-file', '/var/folders/b3/j_ybgjv53p33dy62wlktdr4m0000gp/T/tmpo4m9wguk']
[2021-12-09 19:00:57,333] {standard_task_runner.py:77} INFO - Job 77: Subtask Create_dummy_variables
[2021-12-09 19:01:02,375] {logging_mixin.py:109} INFO - Running <TaskInstance: brent_pricing_dag.Create_dummy_variables manual__2021-12-09T23:54:02.861896+00:00 [running]> on host zipcodes-MacBook-Pro-3.local
[2021-12-09 19:01:07,435] {taskinstance.py:1427} INFO - Exporting the following env vars:
AIRFLOW_CTX_DAG_EMAIL=keerthiballa@gmail.com
AIRFLOW_CTX_DAG_OWNER=airflow
AIRFLOW_CTX_DAG_ID=brent_pricing_dag
AIRFLOW_CTX_TASK_ID=Create_dummy_variables
AIRFLOW_CTX_EXECUTION_DATE=2021-12-09T23:54:02.861896+00:00
AIRFLOW_CTX_DAG_RUN_ID=manual__2021-12-09T23:54:02.861896+00:00
[2021-12-09 19:01:07,489] {taskinstance.py:1703} ERROR - Task failed with exception
Traceback (most recent call last):
  File "/Users/ballakeerthi/dev/Airflow/venv/lib/python3.9/site-packages/sqlalchemy/engine/base.py", line 2336, in _wrap_pool_connect
    return fn()
  File "/Users/ballakeerthi/dev/Airflow/venv/lib/python3.9/site-packages/sqlalchemy/pool/base.py", line 304, in unique_connection
    return _ConnectionFairy._checkout(self)
  File "/Users/ballakeerthi/dev/Airflow/venv/lib/python3.9/site-packages/sqlalchemy/pool/base.py", line 778, in _checkout
    fairy = _ConnectionRecord.checkout(pool)
  File "/Users/ballakeerthi/dev/Airflow/venv/lib/python3.9/site-packages/sqlalchemy/pool/base.py", line 495, in checkout
    rec = pool._do_get()
  File "/Users/ballakeerthi/dev/Airflow/venv/lib/python3.9/site-packages/sqlalchemy/pool/impl.py", line 140, in _do_get
    self._dec_overflow()
  File "/Users/ballakeerthi/dev/Airflow/venv/lib/python3.9/site-packages/sqlalchemy/util/langhelpers.py", line 68, in __exit__
    compat.raise_(
  File "/Users/ballakeerthi/dev/Airflow/venv/lib/python3.9/site-packages/sqlalchemy/util/compat.py", line 182, in raise_
    raise exception
  File "/Users/ballakeerthi/dev/Airflow/venv/lib/python3.9/site-packages/sqlalchemy/pool/impl.py", line 137, in _do_get
    return self._create_connection()
  File "/Users/ballakeerthi/dev/Airflow/venv/lib/python3.9/site-packages/sqlalchemy/pool/base.py", line 309, in _create_connection
    return _ConnectionRecord(self)
  File "/Users/ballakeerthi/dev/Airflow/venv/lib/python3.9/site-packages/sqlalchemy/pool/base.py", line 440, in __init__
    self.__connect(first_connect_check=True)
  File "/Users/ballakeerthi/dev/Airflow/venv/lib/python3.9/site-packages/sqlalchemy/pool/base.py", line 661, in __connect
    pool.logger.debug("Error on connect(): %s", e)
  File "/Users/ballakeerthi/dev/Airflow/venv/lib/python3.9/site-packages/sqlalchemy/util/langhelpers.py", line 68, in __exit__
    compat.raise_(
  File "/Users/ballakeerthi/dev/Airflow/venv/lib/python3.9/site-packages/sqlalchemy/util/compat.py", line 182, in raise_
    raise exception
  File "/Users/ballakeerthi/dev/Airflow/venv/lib/python3.9/site-packages/sqlalchemy/pool/base.py", line 656, in __connect
    connection = pool._invoke_creator(self)
  File "/Users/ballakeerthi/dev/Airflow/venv/lib/python3.9/site-packages/sqlalchemy/engine/strategies.py", line 114, in connect
    return dialect.connect(*cargs, **cparams)
  File "/Users/ballakeerthi/dev/Airflow/venv/lib/python3.9/site-packages/sqlalchemy/engine/default.py", line 508, in connect
    return self.dbapi.connect(*cargs, **cparams)
  File "/Users/ballakeerthi/dev/Airflow/venv/lib/python3.9/site-packages/pymysql/connections.py", line 353, in __init__
    self.connect()
  File "/Users/ballakeerthi/dev/Airflow/venv/lib/python3.9/site-packages/pymysql/connections.py", line 633, in connect
    self._request_authentication()
  File "/Users/ballakeerthi/dev/Airflow/venv/lib/python3.9/site-packages/pymysql/connections.py", line 932, in _request_authentication
    auth_packet = _auth.caching_sha2_password_auth(self, auth_packet)
  File "/Users/ballakeerthi/dev/Airflow/venv/lib/python3.9/site-packages/pymysql/_auth.py", line 239, in caching_sha2_password_auth
    pkt = conn._read_packet()
  File "/Users/ballakeerthi/dev/Airflow/venv/lib/python3.9/site-packages/pymysql/connections.py", line 725, in _read_packet
    packet.raise_for_error()
  File "/Users/ballakeerthi/dev/Airflow/venv/lib/python3.9/site-packages/pymysql/protocol.py", line 221, in raise_for_error
    err.raise_mysql_exception(self._data)
  File "/Users/ballakeerthi/dev/Airflow/venv/lib/python3.9/site-packages/pymysql/err.py", line 143, in raise_mysql_exception
    raise errorclass(errno, errval)
pymysql.err.OperationalError: (1049, "Unknown database 'brent_pricing_db'")

The above exception was the direct cause of the following exception:

Traceback (most recent call last):
  File "/Users/ballakeerthi/dev/Airflow/venv/lib/python3.9/site-packages/airflow/models/taskinstance.py", line 1332, in _run_raw_task
    self._execute_task_with_callbacks(context)
  File "/Users/ballakeerthi/dev/Airflow/venv/lib/python3.9/site-packages/airflow/models/taskinstance.py", line 1458, in _execute_task_with_callbacks
    result = self._execute_task(context, self.task)
  File "/Users/ballakeerthi/dev/Airflow/venv/lib/python3.9/site-packages/airflow/models/taskinstance.py", line 1514, in _execute_task
    result = execute_callable(context=context)
  File "/Users/ballakeerthi/dev/Airflow/venv/lib/python3.9/site-packages/airflow/operators/python.py", line 151, in execute
    return_value = self.execute_callable()
  File "/Users/ballakeerthi/dev/Airflow/venv/lib/python3.9/site-packages/airflow/operators/python.py", line 162, in execute_callable
    return self.python_callable(*self.op_args, **self.op_kwargs)
  File "/Users/ballakeerthi/dev/airflow/dags/brent_ML_reg_models.py", line 79, in create_dummy_vars
    dbConnection = sqlEngine.connect()
  File "/Users/ballakeerthi/dev/Airflow/venv/lib/python3.9/site-packages/sqlalchemy/engine/base.py", line 2263, in connect
    return self._connection_cls(self, **kwargs)
  File "/Users/ballakeerthi/dev/Airflow/venv/lib/python3.9/site-packages/sqlalchemy/engine/base.py", line 104, in __init__
    else engine.raw_connection()
  File "/Users/ballakeerthi/dev/Airflow/venv/lib/python3.9/site-packages/sqlalchemy/engine/base.py", line 2369, in raw_connection
    return self._wrap_pool_connect(
  File "/Users/ballakeerthi/dev/Airflow/venv/lib/python3.9/site-packages/sqlalchemy/engine/base.py", line 2339, in _wrap_pool_connect
    Connection._handle_dbapi_exception_noconnection(
  File "/Users/ballakeerthi/dev/Airflow/venv/lib/python3.9/site-packages/sqlalchemy/engine/base.py", line 1583, in _handle_dbapi_exception_noconnection
    util.raise_(
  File "/Users/ballakeerthi/dev/Airflow/venv/lib/python3.9/site-packages/sqlalchemy/util/compat.py", line 182, in raise_
    raise exception
  File "/Users/ballakeerthi/dev/Airflow/venv/lib/python3.9/site-packages/sqlalchemy/engine/base.py", line 2336, in _wrap_pool_connect
    return fn()
  File "/Users/ballakeerthi/dev/Airflow/venv/lib/python3.9/site-packages/sqlalchemy/pool/base.py", line 304, in unique_connection
    return _ConnectionFairy._checkout(self)
  File "/Users/ballakeerthi/dev/Airflow/venv/lib/python3.9/site-packages/sqlalchemy/pool/base.py", line 778, in _checkout
    fairy = _ConnectionRecord.checkout(pool)
  File "/Users/ballakeerthi/dev/Airflow/venv/lib/python3.9/site-packages/sqlalchemy/pool/base.py", line 495, in checkout
    rec = pool._do_get()
  File "/Users/ballakeerthi/dev/Airflow/venv/lib/python3.9/site-packages/sqlalchemy/pool/impl.py", line 140, in _do_get
    self._dec_overflow()
  File "/Users/ballakeerthi/dev/Airflow/venv/lib/python3.9/site-packages/sqlalchemy/util/langhelpers.py", line 68, in __exit__
    compat.raise_(
  File "/Users/ballakeerthi/dev/Airflow/venv/lib/python3.9/site-packages/sqlalchemy/util/compat.py", line 182, in raise_
    raise exception
  File "/Users/ballakeerthi/dev/Airflow/venv/lib/python3.9/site-packages/sqlalchemy/pool/impl.py", line 137, in _do_get
    return self._create_connection()
  File "/Users/ballakeerthi/dev/Airflow/venv/lib/python3.9/site-packages/sqlalchemy/pool/base.py", line 309, in _create_connection
    return _ConnectionRecord(self)
  File "/Users/ballakeerthi/dev/Airflow/venv/lib/python3.9/site-packages/sqlalchemy/pool/base.py", line 440, in __init__
    self.__connect(first_connect_check=True)
  File "/Users/ballakeerthi/dev/Airflow/venv/lib/python3.9/site-packages/sqlalchemy/pool/base.py", line 661, in __connect
    pool.logger.debug("Error on connect(): %s", e)
  File "/Users/ballakeerthi/dev/Airflow/venv/lib/python3.9/site-packages/sqlalchemy/util/langhelpers.py", line 68, in __exit__
    compat.raise_(
  File "/Users/ballakeerthi/dev/Airflow/venv/lib/python3.9/site-packages/sqlalchemy/util/compat.py", line 182, in raise_
    raise exception
  File "/Users/ballakeerthi/dev/Airflow/venv/lib/python3.9/site-packages/sqlalchemy/pool/base.py", line 656, in __connect
    connection = pool._invoke_creator(self)
  File "/Users/ballakeerthi/dev/Airflow/venv/lib/python3.9/site-packages/sqlalchemy/engine/strategies.py", line 114, in connect
    return dialect.connect(*cargs, **cparams)
  File "/Users/ballakeerthi/dev/Airflow/venv/lib/python3.9/site-packages/sqlalchemy/engine/default.py", line 508, in connect
    return self.dbapi.connect(*cargs, **cparams)
  File "/Users/ballakeerthi/dev/Airflow/venv/lib/python3.9/site-packages/pymysql/connections.py", line 353, in __init__
    self.connect()
  File "/Users/ballakeerthi/dev/Airflow/venv/lib/python3.9/site-packages/pymysql/connections.py", line 633, in connect
    self._request_authentication()
  File "/Users/ballakeerthi/dev/Airflow/venv/lib/python3.9/site-packages/pymysql/connections.py", line 932, in _request_authentication
    auth_packet = _auth.caching_sha2_password_auth(self, auth_packet)
  File "/Users/ballakeerthi/dev/Airflow/venv/lib/python3.9/site-packages/pymysql/_auth.py", line 239, in caching_sha2_password_auth
    pkt = conn._read_packet()
  File "/Users/ballakeerthi/dev/Airflow/venv/lib/python3.9/site-packages/pymysql/connections.py", line 725, in _read_packet
    packet.raise_for_error()
  File "/Users/ballakeerthi/dev/Airflow/venv/lib/python3.9/site-packages/pymysql/protocol.py", line 221, in raise_for_error
    err.raise_mysql_exception(self._data)
  File "/Users/ballakeerthi/dev/Airflow/venv/lib/python3.9/site-packages/pymysql/err.py", line 143, in raise_mysql_exception
    raise errorclass(errno, errval)
sqlalchemy.exc.OperationalError: (pymysql.err.OperationalError) (1049, "Unknown database 'brent_pricing_db'")
(Background on this error at: http://sqlalche.me/e/13/e3q8)
[2021-12-09 19:01:07,515] {taskinstance.py:1270} INFO - Marking task as FAILED. dag_id=brent_pricing_dag, task_id=Create_dummy_variables, execution_date=20211209T235402, start_date=20211210T000057, end_date=20211210T000107
[2021-12-09 19:01:07,525] {standard_task_runner.py:88} ERROR - Failed to execute job 77 for task Create_dummy_variables
Traceback (most recent call last):
  File "/Users/ballakeerthi/dev/Airflow/venv/lib/python3.9/site-packages/sqlalchemy/engine/base.py", line 2336, in _wrap_pool_connect
    return fn()
  File "/Users/ballakeerthi/dev/Airflow/venv/lib/python3.9/site-packages/sqlalchemy/pool/base.py", line 304, in unique_connection
    return _ConnectionFairy._checkout(self)
  File "/Users/ballakeerthi/dev/Airflow/venv/lib/python3.9/site-packages/sqlalchemy/pool/base.py", line 778, in _checkout
    fairy = _ConnectionRecord.checkout(pool)
  File "/Users/ballakeerthi/dev/Airflow/venv/lib/python3.9/site-packages/sqlalchemy/pool/base.py", line 495, in checkout
    rec = pool._do_get()
  File "/Users/ballakeerthi/dev/Airflow/venv/lib/python3.9/site-packages/sqlalchemy/pool/impl.py", line 140, in _do_get
    self._dec_overflow()
  File "/Users/ballakeerthi/dev/Airflow/venv/lib/python3.9/site-packages/sqlalchemy/util/langhelpers.py", line 68, in __exit__
    compat.raise_(
  File "/Users/ballakeerthi/dev/Airflow/venv/lib/python3.9/site-packages/sqlalchemy/util/compat.py", line 182, in raise_
    raise exception
  File "/Users/ballakeerthi/dev/Airflow/venv/lib/python3.9/site-packages/sqlalchemy/pool/impl.py", line 137, in _do_get
    return self._create_connection()
  File "/Users/ballakeerthi/dev/Airflow/venv/lib/python3.9/site-packages/sqlalchemy/pool/base.py", line 309, in _create_connection
    return _ConnectionRecord(self)
  File "/Users/ballakeerthi/dev/Airflow/venv/lib/python3.9/site-packages/sqlalchemy/pool/base.py", line 440, in __init__
    self.__connect(first_connect_check=True)
  File "/Users/ballakeerthi/dev/Airflow/venv/lib/python3.9/site-packages/sqlalchemy/pool/base.py", line 661, in __connect
    pool.logger.debug("Error on connect(): %s", e)
  File "/Users/ballakeerthi/dev/Airflow/venv/lib/python3.9/site-packages/sqlalchemy/util/langhelpers.py", line 68, in __exit__
    compat.raise_(
  File "/Users/ballakeerthi/dev/Airflow/venv/lib/python3.9/site-packages/sqlalchemy/util/compat.py", line 182, in raise_
    raise exception
  File "/Users/ballakeerthi/dev/Airflow/venv/lib/python3.9/site-packages/sqlalchemy/pool/base.py", line 656, in __connect
    connection = pool._invoke_creator(self)
  File "/Users/ballakeerthi/dev/Airflow/venv/lib/python3.9/site-packages/sqlalchemy/engine/strategies.py", line 114, in connect
    return dialect.connect(*cargs, **cparams)
  File "/Users/ballakeerthi/dev/Airflow/venv/lib/python3.9/site-packages/sqlalchemy/engine/default.py", line 508, in connect
    return self.dbapi.connect(*cargs, **cparams)
  File "/Users/ballakeerthi/dev/Airflow/venv/lib/python3.9/site-packages/pymysql/connections.py", line 353, in __init__
    self.connect()
  File "/Users/ballakeerthi/dev/Airflow/venv/lib/python3.9/site-packages/pymysql/connections.py", line 633, in connect
    self._request_authentication()
  File "/Users/ballakeerthi/dev/Airflow/venv/lib/python3.9/site-packages/pymysql/connections.py", line 932, in _request_authentication
    auth_packet = _auth.caching_sha2_password_auth(self, auth_packet)
  File "/Users/ballakeerthi/dev/Airflow/venv/lib/python3.9/site-packages/pymysql/_auth.py", line 239, in caching_sha2_password_auth
    pkt = conn._read_packet()
  File "/Users/ballakeerthi/dev/Airflow/venv/lib/python3.9/site-packages/pymysql/connections.py", line 725, in _read_packet
    packet.raise_for_error()
  File "/Users/ballakeerthi/dev/Airflow/venv/lib/python3.9/site-packages/pymysql/protocol.py", line 221, in raise_for_error
    err.raise_mysql_exception(self._data)
  File "/Users/ballakeerthi/dev/Airflow/venv/lib/python3.9/site-packages/pymysql/err.py", line 143, in raise_mysql_exception
    raise errorclass(errno, errval)
pymysql.err.OperationalError: (1049, "Unknown database 'brent_pricing_db'")

The above exception was the direct cause of the following exception:

Traceback (most recent call last):
  File "/Users/ballakeerthi/dev/Airflow/venv/lib/python3.9/site-packages/airflow/task/task_runner/standard_task_runner.py", line 85, in _start_by_fork
    args.func(args, dag=self.dag)
  File "/Users/ballakeerthi/dev/Airflow/venv/lib/python3.9/site-packages/airflow/cli/cli_parser.py", line 48, in command
    return func(*args, **kwargs)
  File "/Users/ballakeerthi/dev/Airflow/venv/lib/python3.9/site-packages/airflow/utils/cli.py", line 92, in wrapper
    return f(*args, **kwargs)
  File "/Users/ballakeerthi/dev/Airflow/venv/lib/python3.9/site-packages/airflow/cli/commands/task_command.py", line 292, in task_run
    _run_task_by_selected_method(args, dag, ti)
  File "/Users/ballakeerthi/dev/Airflow/venv/lib/python3.9/site-packages/airflow/cli/commands/task_command.py", line 107, in _run_task_by_selected_method
    _run_raw_task(args, ti)
  File "/Users/ballakeerthi/dev/Airflow/venv/lib/python3.9/site-packages/airflow/cli/commands/task_command.py", line 180, in _run_raw_task
    ti._run_raw_task(
  File "/Users/ballakeerthi/dev/Airflow/venv/lib/python3.9/site-packages/airflow/utils/session.py", line 70, in wrapper
    return func(*args, session=session, **kwargs)
  File "/Users/ballakeerthi/dev/Airflow/venv/lib/python3.9/site-packages/airflow/models/taskinstance.py", line 1332, in _run_raw_task
    self._execute_task_with_callbacks(context)
  File "/Users/ballakeerthi/dev/Airflow/venv/lib/python3.9/site-packages/airflow/models/taskinstance.py", line 1458, in _execute_task_with_callbacks
    result = self._execute_task(context, self.task)
  File "/Users/ballakeerthi/dev/Airflow/venv/lib/python3.9/site-packages/airflow/models/taskinstance.py", line 1514, in _execute_task
    result = execute_callable(context=context)
  File "/Users/ballakeerthi/dev/Airflow/venv/lib/python3.9/site-packages/airflow/operators/python.py", line 151, in execute
    return_value = self.execute_callable()
  File "/Users/ballakeerthi/dev/Airflow/venv/lib/python3.9/site-packages/airflow/operators/python.py", line 162, in execute_callable
    return self.python_callable(*self.op_args, **self.op_kwargs)
  File "/Users/ballakeerthi/dev/airflow/dags/brent_ML_reg_models.py", line 79, in create_dummy_vars
    dbConnection = sqlEngine.connect()
  File "/Users/ballakeerthi/dev/Airflow/venv/lib/python3.9/site-packages/sqlalchemy/engine/base.py", line 2263, in connect
    return self._connection_cls(self, **kwargs)
  File "/Users/ballakeerthi/dev/Airflow/venv/lib/python3.9/site-packages/sqlalchemy/engine/base.py", line 104, in __init__
    else engine.raw_connection()
  File "/Users/ballakeerthi/dev/Airflow/venv/lib/python3.9/site-packages/sqlalchemy/engine/base.py", line 2369, in raw_connection
    return self._wrap_pool_connect(
  File "/Users/ballakeerthi/dev/Airflow/venv/lib/python3.9/site-packages/sqlalchemy/engine/base.py", line 2339, in _wrap_pool_connect
    Connection._handle_dbapi_exception_noconnection(
  File "/Users/ballakeerthi/dev/Airflow/venv/lib/python3.9/site-packages/sqlalchemy/engine/base.py", line 1583, in _handle_dbapi_exception_noconnection
    util.raise_(
  File "/Users/ballakeerthi/dev/Airflow/venv/lib/python3.9/site-packages/sqlalchemy/util/compat.py", line 182, in raise_
    raise exception
  File "/Users/ballakeerthi/dev/Airflow/venv/lib/python3.9/site-packages/sqlalchemy/engine/base.py", line 2336, in _wrap_pool_connect
    return fn()
  File "/Users/ballakeerthi/dev/Airflow/venv/lib/python3.9/site-packages/sqlalchemy/pool/base.py", line 304, in unique_connection
    return _ConnectionFairy._checkout(self)
  File "/Users/ballakeerthi/dev/Airflow/venv/lib/python3.9/site-packages/sqlalchemy/pool/base.py", line 778, in _checkout
    fairy = _ConnectionRecord.checkout(pool)
  File "/Users/ballakeerthi/dev/Airflow/venv/lib/python3.9/site-packages/sqlalchemy/pool/base.py", line 495, in checkout
    rec = pool._do_get()
  File "/Users/ballakeerthi/dev/Airflow/venv/lib/python3.9/site-packages/sqlalchemy/pool/impl.py", line 140, in _do_get
    self._dec_overflow()
  File "/Users/ballakeerthi/dev/Airflow/venv/lib/python3.9/site-packages/sqlalchemy/util/langhelpers.py", line 68, in __exit__
    compat.raise_(
  File "/Users/ballakeerthi/dev/Airflow/venv/lib/python3.9/site-packages/sqlalchemy/util/compat.py", line 182, in raise_
    raise exception
  File "/Users/ballakeerthi/dev/Airflow/venv/lib/python3.9/site-packages/sqlalchemy/pool/impl.py", line 137, in _do_get
    return self._create_connection()
  File "/Users/ballakeerthi/dev/Airflow/venv/lib/python3.9/site-packages/sqlalchemy/pool/base.py", line 309, in _create_connection
    return _ConnectionRecord(self)
  File "/Users/ballakeerthi/dev/Airflow/venv/lib/python3.9/site-packages/sqlalchemy/pool/base.py", line 440, in __init__
    self.__connect(first_connect_check=True)
  File "/Users/ballakeerthi/dev/Airflow/venv/lib/python3.9/site-packages/sqlalchemy/pool/base.py", line 661, in __connect
    pool.logger.debug("Error on connect(): %s", e)
  File "/Users/ballakeerthi/dev/Airflow/venv/lib/python3.9/site-packages/sqlalchemy/util/langhelpers.py", line 68, in __exit__
    compat.raise_(
  File "/Users/ballakeerthi/dev/Airflow/venv/lib/python3.9/site-packages/sqlalchemy/util/compat.py", line 182, in raise_
    raise exception
  File "/Users/ballakeerthi/dev/Airflow/venv/lib/python3.9/site-packages/sqlalchemy/pool/base.py", line 656, in __connect
    connection = pool._invoke_creator(self)
  File "/Users/ballakeerthi/dev/Airflow/venv/lib/python3.9/site-packages/sqlalchemy/engine/strategies.py", line 114, in connect
    return dialect.connect(*cargs, **cparams)
  File "/Users/ballakeerthi/dev/Airflow/venv/lib/python3.9/site-packages/sqlalchemy/engine/default.py", line 508, in connect
    return self.dbapi.connect(*cargs, **cparams)
  File "/Users/ballakeerthi/dev/Airflow/venv/lib/python3.9/site-packages/pymysql/connections.py", line 353, in __init__
    self.connect()
  File "/Users/ballakeerthi/dev/Airflow/venv/lib/python3.9/site-packages/pymysql/connections.py", line 633, in connect
    self._request_authentication()
  File "/Users/ballakeerthi/dev/Airflow/venv/lib/python3.9/site-packages/pymysql/connections.py", line 932, in _request_authentication
    auth_packet = _auth.caching_sha2_password_auth(self, auth_packet)
  File "/Users/ballakeerthi/dev/Airflow/venv/lib/python3.9/site-packages/pymysql/_auth.py", line 239, in caching_sha2_password_auth
    pkt = conn._read_packet()
  File "/Users/ballakeerthi/dev/Airflow/venv/lib/python3.9/site-packages/pymysql/connections.py", line 725, in _read_packet
    packet.raise_for_error()
  File "/Users/ballakeerthi/dev/Airflow/venv/lib/python3.9/site-packages/pymysql/protocol.py", line 221, in raise_for_error
    err.raise_mysql_exception(self._data)
  File "/Users/ballakeerthi/dev/Airflow/venv/lib/python3.9/site-packages/pymysql/err.py", line 143, in raise_mysql_exception
    raise errorclass(errno, errval)
sqlalchemy.exc.OperationalError: (pymysql.err.OperationalError) (1049, "Unknown database 'brent_pricing_db'")
(Background on this error at: http://sqlalche.me/e/13/e3q8)
[2021-12-09 19:01:07,556] {local_task_job.py:154} INFO - Task exited with return code 1
[2021-12-09 19:01:07,587] {local_task_job.py:264} INFO - 0 downstream tasks scheduled from follow-on schedule check
